<?xml version="1.0" ?>
<!-- =================================================================================== -->
<!-- |    This document was autogenerated by xacro from denso_robot.urdf.xacro         | -->
<!-- |    EDITING THIS FILE BY HAND IS NOT RECOMMENDED                                 | -->
<!-- =================================================================================== -->
<robot name="denso_robot">
  <!-- create link fixed to the "world" -->
  <link name="world"/>
  <!-- LINKS -->
  <!-- base link -->
  <link name="base_link">
    <inertial>
      <origin rpy="0 0 0" xyz="0 0 0"/>
      <mass value="1"/>
      <inertia ixx="1" ixy="0.0" ixz="0.0" iyy="1" iyz="0.0" izz="1"/>
    </inertial>
    <visual>
      <origin rpy="0 0 0" xyz="0 0 0"/>
      <geometry>
        <mesh filename="package://denso_robot_description/meshes/denso_robot/visual/base_link.dae"/>
      </geometry>
    </visual>
    <collision>
      <origin rpy="0 0 0" xyz="0 0 0"/>
      <geometry>
        <mesh filename="package://denso_robot_description/meshes/denso_robot/visual/base_link.dae"/>
      </geometry>
    </collision>
  </link>
  <!-- link 1 -->
  <link name="link1">
    <inertial>
      <origin rpy="0 0 0" xyz="0 0 0"/>
      <mass value="1"/>
      <inertia ixx="1" ixy="0.0" ixz="0.0" iyy="1" iyz="0.0" izz="1"/>
    </inertial>
    <visual>
      <origin rpy="0 0 0" xyz="0 0 0"/>
      <geometry>
        <mesh filename="package://denso_robot_description/meshes/denso_robot/visual/J1.dae"/>
      </geometry>
    </visual>
    <collision>
      <origin rpy="0 0 0" xyz="0 0 0"/>
      <geometry>
        <mesh filename="package://denso_robot_description/meshes/denso_robot/visual/J1.dae"/>
      </geometry>
    </collision>
  </link>
  <!-- link 2 -->
  <link name="link2">
    <inertial>
      <origin rpy="0 0 0" xyz="0 0 0"/>
      <mass value="1"/>
      <inertia ixx="1" ixy="0.0" ixz="0.0" iyy="1" iyz="0.0" izz="1"/>
    </inertial>
    <visual>
      <origin rpy="0 0 0" xyz="0 0 0"/>
      <geometry>
        <mesh filename="package://denso_robot_description/meshes/denso_robot/visual/J2.dae"/>
      </geometry>
    </visual>
    <collision>
      <origin rpy="0 0 0" xyz="0 0 0"/>
      <geometry>
        <mesh filename="package://denso_robot_description/meshes/denso_robot/visual/J2.dae"/>
      </geometry>
    </collision>
  </link>
  <!-- link 3 -->
  <link name="link3">
    <inertial>
      <origin rpy="0 0 0" xyz="0 0 0"/>
      <mass value="1"/>
      <inertia ixx="1" ixy="0.0" ixz="0.0" iyy="1" iyz="0.0" izz="1"/>
    </inertial>
    <visual>
      <origin rpy="0 0 0" xyz="0 0 0"/>
      <geometry>
        <mesh filename="package://denso_robot_description/meshes/denso_robot/visual/J3.dae"/>
      </geometry>
    </visual>
    <collision>
      <origin rpy="0 0 0" xyz="0 0 0"/>
      <geometry>
        <mesh filename="package://denso_robot_description/meshes/denso_robot/visual/J3.dae"/>
      </geometry>
    </collision>
  </link>
  <!-- link 4 -->
  <link name="link4">
    <inertial>
      <origin rpy="0 0 0" xyz="0 0 0"/>
      <mass value="1"/>
      <inertia ixx="1" ixy="0.0" ixz="0.0" iyy="1" iyz="0.0" izz="1"/>
    </inertial>
    <visual>
      <origin rpy="0 0 0" xyz="0 0 0"/>
      <geometry>
        <mesh filename="package://denso_robot_description/meshes/denso_robot/visual/J4.dae"/>
      </geometry>
    </visual>
    <collision>
      <origin rpy="0 0 0" xyz="0 0 0"/>
      <geometry>
        <mesh filename="package://denso_robot_description/meshes/denso_robot/visual/J4.dae"/>
      </geometry>
    </collision>
  </link>
  <!-- link 5 -->
  <link name="link5">
    <inertial>
      <origin rpy="0 0 0" xyz="0 0 0"/>
      <mass value="1"/>
      <inertia ixx="1" ixy="0.0" ixz="0.0" iyy="1" iyz="0.0" izz="1"/>
    </inertial>
    <visual>
      <origin rpy="0 0 0" xyz="0 0 0"/>
      <geometry>
        <mesh filename="package://denso_robot_description/meshes/denso_robot/visual/J5.dae"/>
      </geometry>
    </visual>
    <collision>
      <origin rpy="0 0 0" xyz="0 0 0"/>
      <geometry>
        <mesh filename="package://denso_robot_description/meshes/denso_robot/visual/J5.dae"/>
      </geometry>
    </collision>
  </link>
  <!-- link 6 -->
  <link name="link6">
    <inertial>
      <origin rpy="0 0 0" xyz="0 0 0"/>
      <mass value="1"/>
      <inertia ixx="1" ixy="0.0" ixz="0.0" iyy="1" iyz="0.0" izz="1"/>
    </inertial>
    <visual>
      <origin rpy="0 0 0" xyz="0 0 0"/>
      <geometry>
        <mesh filename="package://denso_robot_description/meshes/denso_robot/visual/J6.dae"/>
      </geometry>
    </visual>
    <collision>
      <origin rpy="0 0 0" xyz="0 0 0"/>
      <geometry>
        <mesh filename="package://denso_robot_description/meshes/denso_robot/visual/J6.dae"/>
      </geometry>
    </collision>
  </link>
  
  <link name="link_ee"/>
  
  <!-- All-zero tool frame. This frame should correspond to the TOOL frame of the robot's controller.) -->
  <link name="tool0"/>
  <!-- tool link -->
  <!-- END LINKS -->
  <!-- JOINTS -->
  <!-- base_joint fixes base_link to the environment -->
  <joint name="base_joint" type="fixed">
    <origin rpy="0 0 0" xyz="0 0 0"/>
    <parent link="world"/>
    <child link="base_link"/>
  </joint>
  <!-- joint 1 -->
  <joint name="joint1" type="revolute">
    <origin rpy="0 0 0" xyz="0 0 0.197500"/>
    <parent link="base_link"/>
    <child link="link1"/>
    <axis xyz="0 0 1"/>
    <limit effort="1000" lower="-2.9670597283903604" upper="2.9670597283903604" velocity="6.283185307179586"/>
    <dynamics damping="0.7" friction="0.0"/>
  </joint>
  <!-- joint 2 -->
  <joint name="joint2" type="revolute">
    <origin rpy="0 0 0" xyz="0.03 0 0.1975"/>
    <parent link="link1"/>
    <child link="link2"/>
    <axis xyz="0 1 0"/>
    <limit effort="1000" lower="-1.7453292519943295" upper="2.356194490192345" velocity="5.235987755982989"/>
    <dynamics damping="0.7" friction="0.0"/>
  </joint>
  <!-- joint 3 -->
  <joint name="joint3" type="revolute">
    <origin rpy="0 0 0" xyz="0 0 0.445"/>
    <parent link="link2"/>
    <child link="link3"/>
    <axis xyz="0 1 0"/>
    <limit effort="1000" lower="-2.3736477827122884" upper="2.670353755551324" velocity="7.120943348136865"/>
    <dynamics damping="0.7" friction="0.0"/>
  </joint>
  <!-- joint 4 -->
  <joint name="joint4" type="revolute">
    <origin rpy="0 0 0" xyz="-0.02 0 0.287"/>
    <parent link="link3"/>
    <child link="link4"/>
    <axis xyz="0 0 1"/>
    <limit effort="1000" lower="-4.71238898038469" upper="4.71238898038469" velocity="9.42477796076938"/>
    <dynamics damping="0.7" friction="0.0"/>
  </joint>
  <!-- joint 5 -->
  <joint name="joint5" type="revolute">
    <origin rpy="0 0 0" xyz="0 0 0.143"/>
    <parent link="link4"/>
    <child link="link5"/>
    <axis xyz="0 1 0"/>
    <limit effort="1000" lower="-2.0943951023931953" upper="2.0943951023931953" velocity="9.42477796076938"/>
    <dynamics damping="0.7" friction="0.0"/>
  </joint>
  <!-- joint 6 -->
  <joint name="joint6" type="revolute">
    <origin rpy="0 0 0" xyz="0 0 0.08"/>
    <parent link="link5"/>
    <child link="link6"/>
    <axis xyz="0 0 1"/>
    <limit effort="1000" lower="-6.283185307179586" upper="6.283185307179586" velocity="15.079644737231007"/>
    <dynamics damping="0.7" friction="0.0"/>
  </joint>
  <!-- tool frame - fixed frame -->
  <joint name="joint6_tool0" type="fixed">
    <parent link="link6"/>
    <child link="tool0"/>
    <origin rpy="0 -3.141592653589793 -1.5707963267948966" xyz="0 0 -0.115"/>
  </joint>
  
  <joint name="joint6_ee" type="fixed">
    <parent link="link6"/>
    <child link="link_ee"/>
    <origin rpy="0 0 0" xyz="0 0 0"/>
  </joint>
  
  <!-- END JOINTS -->
  
  <link name="ati_base_link">
    <inertial>
        <mass value="0.3"/>
        <inertia  ixx="0.002385" ixy="0.00"  ixz="0.00" iyy="0.002385" iyz="0.00" izz="0.00027" />
    </inertial>
    <visual>
        <origin xyz="0 0 0.017" rpy="0 0 0"/>
        <geometry>
            <cylinder length="0.034" radius="0.041"/>
        </geometry>
    </visual>
    <collision>
        <origin xyz="0 0 0.017" rpy="0 0 0"/>
        <geometry>
            <cylinder length="0.034" radius="0.041"/>
        </geometry>
    </collision>
  </link>
  <link name="ati_sensor_link"/>
  
  <link name="robotiq_ati_flange_base_link">
    <inertial>
        <mass value="0.3"/>
        <inertia  ixx="0.002385" ixy="0.00"  ixz="0.00" iyy="0.002385" iyz="0.00" izz="0.00027" />
    </inertial>
    <visual>
        <origin xyz="0 0 0.003" rpy="0 0 0"/>
        <geometry>
            <cylinder length="0.006" radius="0.041"/>
        </geometry>
    </visual>
    <collision>
	<origin xyz="0 0 0.003" rpy="0 0 0"/>
	<geometry>
	    <cylinder length="0.006" radius="0.041"/>
	</geometry>
    </collision>
  </link>
  <link name="robotiq_ati_flange_link"/>
  

  
  <joint name="robotiq_ati_flange_base_joint" type="fixed">
    <parent link="link6" />
    <child link="ati_base_link" />
  </joint>
  <joint name="ati_sensor_joint" type="fixed">
    <parent link="ati_base_link" />
    <child link="ati_sensor_link" />
    <origin xyz="0 0 0.034" rpy="0 0 1.570796" />
  </joint>
  
  <joint name="ati_base_joint" type="fixed">
    <parent link="ati_sensor_link" />
    <child link="robotiq_ati_flange_base_link" />
  </joint>
  
  <joint name="robotiq_ati_flange_joint" type="fixed">
    <parent link="robotiq_ati_flange_base_link" />
    <child link="robotiq_ati_flange_link" />
    <origin xyz="0 0 0.006" rpy="0 0 0" />
  </joint>
  
  <!-- END robot joints -->
  
    
  <!-- leap_hand_link -->
  <link name="palm_lower">
    <visual>
      <origin xyz="-0.020095249652862544332 0.025757756134899473244 -0.034722403578460216134" rpy="0 0 0"/>
      <geometry>
        <mesh filename="package://denso_robot_description/meshes/leap_hand/palm_lower.stl"/>
      </geometry>
      <material name="palm_lower_material">
	<color rgba="0.60392156862745094426 0.14901960784313725283 0.14901960784313725283 1.0"/>
      </material>
    </visual>
    <collision>
      <origin xyz="-0.020095249652862544332 0.025757756134899473244 -0.004722403578460216134" rpy="0 0 0" />
      <geometry>
        <mesh filename="package://denso_robot_description/meshes/leap_hand/palm_lower.stl"/>
      </geometry>
    </collision>
    <inertial>
	<origin xyz="0 0 0" rpy="0 0 0"/>
	<mass value="0.0237" />
	<inertia ixx="0.000354094" ixy="-0.000001193"  ixz="-0.000002445" iyy="0.000260915" iyz="-0.000002905" izz="0.000529257" />
    </inertial>
  </link>
  
  
  <link name="leap_hand_base_link"/>
  
  <joint name="ati_leap_hand_joint" type="fixed">
    <parent link="robotiq_ati_flange_link" />
    <child link="leap_hand_base_link" />
    <origin xyz="0 0 0" rpy="0 0 0" />
  </joint>
  
  <joint name="palm_joint" type="fixed">
    <parent link="leap_hand_base_link" />
    <child link="palm_lower" />
    <origin xyz="0.03424224387 0.060095249652862544332 0.01527759642" rpy="3.14 0 1.570796327" />
  </joint>
  
  <link name="mcp_link">
    <visual>
      <origin xyz="0.0084069022611744960438 0.0077662438597169954416 0.014657354985032912051" rpy="1.6375789613220999807e-15 -1.0210473302491019535e-30 1.7177968783327987474e-31" />
      <geometry>
        <mesh filename="package://denso_robot_description/meshes/leap_hand/mcp_joint.stl"/>
      </geometry>
      <material name="mcp_joint_material">
        <color rgba="0.86666666666666669627 0.86666666666666669627 0.050980392156862744391 1.0"/>
      </material>
    </visual>
    <collision>
      <origin xyz="0.0084069022611744960438 0.0077662438597169954416 0.014657354985032912051" rpy="0 0 0" />
      <geometry>
        <mesh filename="package://denso_robot_description/meshes/leap_hand/mcp_joint.stl"/>
      </geometry>
    </collision>
    <inertial>
      <origin xyz="0 0 0" rpy="0 0 0"/>
      <mass value="0.0044" />
      <inertia ixx="0.000011499" ixy="0.000003049"  ixz="0.000000121" iyy="0.000007796" iyz="0.000000112" izz="0.000014759" />
    </inertial>
  </link>
  
  <link name="pip_link">
    <visual>
      <origin xyz="0.0096433630922713280131 0.00029999999999998951117 0.00078403401041737645627" rpy="-1.570796326794896558 -1.570796326794896336 0" />
      <geometry>
        <mesh filename="package://denso_robot_description/meshes/leap_hand/pip.stl"/>
      </geometry>
      <material name="pip_material">
        <color rgba="0.74901960784313725839 0.74901960784313725839 0.74901960784313725839 1.0"/>
      </material>
    </visual>
    <collision>
      <origin xyz="0.0096433630922713280131 0.00029999999999998951117 0.00078403401041737645627" rpy="-1.570796326794896558 -1.570796326794896336 0" />
      <geometry>
      <mesh filename="package://denso_robot_description/meshes/leap_hand/pip.stl"/>
      </geometry>
    </collision>
    <inertial>
      <origin xyz="0 0 0" rpy="0 0 0"/>
      <mass value="0.0032" />
      <inertia ixx="0.000004798" ixy="0.000000012"  ixz="0.000000004" iyy="0.000002862" iyz="0.000000011" izz="0.000004234" />
    </inertial>
  </link>
  
  <link name="dip_link">
    <visual>
      <origin xyz="0.021133352895225002849 -0.0084321191467048792201 0.0097850881620952408213" rpy="-3.141592653589793116 4.5075111242164408299e-32 4.4395481053923607589e-32" />
      <geometry>
        <mesh filename="package://denso_robot_description/meshes/leap_hand/dip.stl"/>
      </geometry>
      <material name="dip_material">
        <color rgba="0.86666666666666669627 0.86666666666666669627 0.050980392156862744391 1.0"/>
      </material>
    </visual>
    <collision>
      <origin xyz="0.021133352895225002849 -0.0084321191467048792201 0.0097850881620952408213" rpy="-3.141592653589793116 4.5075111242164408299e-32 4.4395481053923607589e-32" />
      <geometry>
        <mesh filename="package://denso_robot_description/meshes/leap_hand/dip.stl"/>
      </geometry>
    </collision>
    <inertial>
      <origin xyz="0 0 0" rpy="0 0 0"/>
      <mass value="0.0037" />
      <inertia ixx="0.000005542" ixy="-0.000000607"  ixz="-0.000000017" iyy="0.000005727" iyz="-0.000000023" izz="0.000006682" />
    </inertial>
  </link>

  <link
    name="fingertip_link">
    <inertial>
      <origin
        xyz="7.5508E-17 0.010974 -0.01509"
        rpy="0 0 0" />
      <mass
        value="0.0027869" />
      <inertia
        ixx="5.7061E-07"
        ixy="-2.8335E-22"
        ixz="-1.3602E-22"
        iyy="5.3815E-07"
        iyz="5.3399E-10"
        izz="2.1614E-07" />
    </inertial>
    <visual>
      <origin
        xyz="0 0 0"
        rpy="0 0 0" />
      <geometry>
        <mesh
          filename="package://denso_robot_description/meshes/fingertip/meshes/fingertip_link.STL" />
      </geometry>
      <material
        name="">
        <color
          rgba="1 1 1 1" />
      </material>
    </visual>
    <collision>
      <origin
        xyz="0 0 0"
        rpy="0 0 0" />
      <geometry>
        <mesh
          filename="package://denso_robot_description/meshes/fingertip/meshes/fingertip_link.STL" />
      </geometry>
    </collision>
  </link>
  <link
    name="connect_link">
    <inertial>
      <origin
        xyz="0.00411765424561172 -0.0148300279082091 0.01775"
        rpy="0 0 0" />
      <mass
        value="0.00557866650364624" />
      <inertia
        ixx="1.54542696836901E-06"
        ixy="-1.85486908918896E-07"
        ixz="-5.33126863056774E-23"
        iyy="7.02952909902168E-07"
        iyz="1.50767782807126E-22"
        izz="1.09293721480962E-06" />
    </inertial>
    <visual>
      <origin
        xyz="0 0 0"
        rpy="0 0 0" />
      <geometry>
        <mesh
          filename="package://denso_robot_description/meshes/fingertip/meshes/connect_link.STL" />
      </geometry>
      <material
        name="">
        <color
          rgba="1 1 1 1" />
      </material>
    </visual>
    <collision>
      <origin
        xyz="0 0 0"
        rpy="0 0 0" />
      <geometry>
        <mesh
          filename="package://denso_robot_description/meshes/fingertip/meshes/connect_link.STL" />
      </geometry>
    </collision>
  </link>
  
  <link
    name="sensor_link">
    <inertial>
      <origin
        xyz="5.4530562509196E-06 0.0133276953059358 -5.04567839394631E-05"
        rpy="0 0 0" />
      <mass
        value="0.0178822084472655" />
      <inertia
        ixx="1.1753392286897E-06"
        ixy="4.11684437842668E-12"
        ixz="-2.43892475857913E-11"
        iyy="2.53546070358439E-06"
        iyz="-2.92731609599381E-09"
        izz="1.78912273862224E-06" />
    </inertial>
    <visual>
      <origin
        xyz="0 0 0"
        rpy="0 0 0" />
      <geometry>
        <mesh
          filename="package://denso_robot_description/meshes/fingertip/meshes/sensor_link.STL" />
      </geometry>
      <material
        name="">
        <color
          rgba="1 1 1 1" />
      </material>
    </visual>
    <collision>
      <origin
        xyz="0 0 0"
        rpy="0 0 0" />
      <geometry>
        <mesh
          filename="package://denso_robot_description/meshes/fingertip/meshes/sensor_link.STL" />
      </geometry>
    </collision>
  </link>
  
  <!-- CREATE HAND LINK 2-->
  <link name="mcp_link_2">
    <visual>
      <origin xyz="0.0084069022611744960438 0.0077662438597169954416 0.014657354985032913786" rpy="1.6375789613220999807e-15 -1.0076465469034000467e-30 2.1209300131419907151e-61" />
      <geometry>
        <mesh filename="package://denso_robot_description/meshes/leap_hand/mcp_joint.stl"/>
      </geometry>
      <material name="mcp_joint_material">
        <color rgba="0.86666666666666669627 0.86666666666666669627 0.050980392156862744391 1.0"/>
      </material>
    </visual>
    <collision>
      <origin xyz="0.0084069022611744960438 0.0077662438597169954416 0.014657354985032913786" rpy="1.6375789613220999807e-15 -1.0076465469034000467e-30 2.1209300131419907151e-61" />
      <geometry>
        <mesh filename="package://denso_robot_description/meshes/leap_hand/mcp_joint.stl"/>
      </geometry>
    </collision>
    <inertial>
      <origin xyz="0 0 0" rpy="0 0 0"/>
      <mass value="0.0044" />
      <inertia ixx="0.000011499" ixy="0.000003049"  ixz="0.000000121" iyy="0.000007796" iyz="0.000000112" izz="0.000014759" />
    </inertial>
  </link>

  <link name="pip_link_2">
    <visual>
      <origin xyz="0.0096433630922713280131 0.00029999999999999471534 0.00078403401041737645627" rpy="-1.570796326794896558 -1.570796326794896336 0" />
      <geometry>
        <mesh filename="package://denso_robot_description/meshes/leap_hand/pip.stl"/>
      </geometry>
      <material name="pip_material">
        <color rgba="0.74901960784313725839 0.74901960784313725839 0.74901960784313725839 1.0"/>
      </material>
    </visual>
    <collision>
      <origin xyz="0.0096433630922713280131 0.00029999999999999471534 0.00078403401041737645627" rpy="-1.570796326794896558 -1.570796326794896336 0" />
      <geometry>
        <mesh filename="package://denso_robot_description/meshes/leap_hand/pip.stl"/>
      </geometry>
    </collision>
    <inertial>
      <origin xyz="0 0 0" rpy="0 0 0"/>
      <mass value="0.0032" />
      <inertia ixx="0.000004798" ixy="0.000000012"  ixz="0.000000004" iyy="0.000002862" iyz="0.000000011" izz="0.000004234" />
    </inertial>
  </link>

  <link name="dip_link_2">
    <visual>
      <origin xyz="0.021133352895225002849 -0.0084321191467048653423 0.0097850881620952373519" rpy="-3.141592653589793116 2.1146933785271955805e-32 1.4408183216511868558e-31" />
      <geometry>
        <mesh filename="package://denso_robot_description/meshes/leap_hand/dip.stl"/>
      </geometry>
      <material name="dip_material">
        <color rgba="0.86666666666666669627 0.86666666666666669627 0.050980392156862744391 1.0"/>
      </material>
    </visual>
    <collision>
      <origin xyz="0.021133352895225002849 -0.0084321191467048653423 0.0097850881620952373519" rpy="-3.141592653589793116 2.1146933785271955805e-32 1.4408183216511868558e-31" />
      <geometry>
        <mesh filename="package://denso_robot_description/meshes/leap_hand/dip.stl"/>
      </geometry>
    </collision>
    <inertial>
      <origin xyz="0 0 0" rpy="0 0 0"/>
      <mass value="0.0037" />
      <inertia ixx="0.000005542" ixy="-0.000000607"  ixz="-0.000000017" iyy="0.000005727" iyz="-0.000000023" izz="0.000006682" />
    </inertial>
  </link>

  <link
    name="fingertip_link_2">
    <inertial>
      <origin
        xyz="7.5508E-17 0.010974 -0.01509"
        rpy="0 0 0" />
      <mass
        value="0.0027869" />
      <inertia
        ixx="5.7061E-07"
        ixy="-2.8335E-22"
        ixz="-1.3602E-22"
        iyy="5.3815E-07"
        iyz="5.3399E-10"
        izz="2.1614E-07" />
    </inertial>
    <visual>
      <origin
        xyz="0 0 0"
        rpy="0 0 0" />
      <geometry>
        <mesh
          filename="package://denso_robot_description/meshes/fingertip/meshes/fingertip_link.STL" />
      </geometry>
      <material
        name="">
        <color
          rgba="1 1 1 1" />
      </material>
    </visual>
    <collision>
      <origin
        xyz="0 0 0"
        rpy="0 0 0" />
      <geometry>
        <mesh
          filename="package://denso_robot_description/meshes/fingertip/meshes/fingertip_link.STL" />
      </geometry>
    </collision>
  </link>
  <link
    name="connect_link_2">
    <inertial>
      <origin
        xyz="0.00411765424561172 -0.0148300279082091 0.01775"
        rpy="0 0 0" />
      <mass
        value="0.00557866650364624" />
      <inertia
        ixx="1.54542696836901E-06"
        ixy="-1.85486908918896E-07"
        ixz="-5.33126863056774E-23"
        iyy="7.02952909902168E-07"
        iyz="1.50767782807126E-22"
        izz="1.09293721480962E-06" />
    </inertial>
    <visual>
      <origin
        xyz="0 0 0"
        rpy="0 0 0" />
      <geometry>
        <mesh
          filename="package://denso_robot_description/meshes/fingertip/meshes/connect_link.STL" />
      </geometry>
      <material
        name="">
        <color
          rgba="1 1 1 1" />
      </material>
    </visual>
    <collision>
      <origin
        xyz="0 0 0"
        rpy="0 0 0" />
      <geometry>
        <mesh
          filename="package://denso_robot_description/meshes/fingertip/meshes/connect_link.STL" />
      </geometry>
    </collision>
  </link>
  
  <link
    name="sensor_link_2">
    <inertial>
      <origin
        xyz="5.4530562509196E-06 0.0133276953059358 -5.04567839394631E-05"
        rpy="0 0 0" />
      <mass
        value="0.0178822084472655" />
      <inertia
        ixx="1.1753392286897E-06"
        ixy="4.11684437842668E-12"
        ixz="-2.43892475857913E-11"
        iyy="2.53546070358439E-06"
        iyz="-2.92731609599381E-09"
        izz="1.78912273862224E-06" />
    </inertial>
    <visual>
      <origin
        xyz="0 0 0"
        rpy="0 0 0" />
      <geometry>
        <mesh
          filename="package://denso_robot_description/meshes/fingertip/meshes/sensor_link.STL" />
      </geometry>
      <material
        name="">
        <color
          rgba="1 1 1 1" />
      </material>
    </visual>
    <collision>
      <origin
        xyz="0 0 0"
        rpy="0 0 0" />
      <geometry>
        <mesh
          filename="package://denso_robot_description/meshes/fingertip/meshes/sensor_link.STL" />
      </geometry>
    </collision>
  </link>

  <!-- CREATE HAND LINK 3-->
  <link name="mcp_link_3">
    <visual>
      <origin xyz="0.0084069022611744995133 0.0077662438597169963089 0.014657354985032913786" rpy="1.6375789613220999807e-15 -1.0059504988632626953e-30 5.729641584552035421e-32" />
      <geometry>
        <mesh filename="package://denso_robot_description/meshes/leap_hand/mcp_joint.stl"/>
      </geometry>
      <material name="mcp_joint_material">
        <color rgba="0.86666666666666669627 0.86666666666666669627 0.050980392156862744391 1.0"/>
      </material>
    </visual>
    <collision>
      <origin xyz="0.0084069022611744995133 0.0077662438597169963089 0.014657354985032913786" rpy="1.6375789613220999807e-15 -1.0059504988632626953e-30 5.729641584552035421e-32" />
      <geometry>
        <mesh filename="package://denso_robot_description/meshes/leap_hand/mcp_joint.stl"/>
      </geometry>
    </collision>
    <inertial>
      <origin xyz="0 0 0" rpy="0 0 0"/>
      <mass value="0.0044" />
      <inertia ixx="0.000011499" ixy="0.000003049"  ixz="0.000000121" iyy="0.000007796" iyz="0.000000112" izz="0.000014759" />
    </inertial>
  </link>


  <link name="pip_link_3">
    <visual>
      <origin xyz="0.0096433630922713314826 0.00029999999999998083755 0.00078403401041737645627" rpy="-1.570796326794896558 -1.570796326794896336 0" />
      <geometry>
        <mesh filename="package://denso_robot_description/meshes/leap_hand/pip.stl"/>
      </geometry>
      <material name="pip_material">
        <color rgba="0.74901960784313725839 0.74901960784313725839 0.74901960784313725839 1.0"/>
      </material>
    </visual>
    <collision>
      <origin xyz="0.0096433630922713314826 0.00029999999999998083755 0.00078403401041737645627" rpy="-1.570796326794896558 -1.570796326794896336 0" />
      <geometry>
        <mesh filename="package://denso_robot_description/meshes/leap_hand/pip.stl"/>
      </geometry>
    </collision>
    <inertial>
      <origin xyz="0 0 0" rpy="0 0 0"/>
      <mass value="0.0032" />
      <inertia ixx="0.000004798" ixy="0.000000012"  ixz="0.000000004" iyy="0.000002862" iyz="0.000000011" izz="0.000004234" />
    </inertial>
  </link> 

  <link name="dip_link_3">
    <visual>
      <origin xyz="0.021133352895225006318 -0.0084321191467048653423 0.0097850881620952373519" rpy="-3.141592653589793116 -1.4095651113919093005e-33 1.5565411607615035382e-32" />
      <geometry>
        <mesh filename="package://denso_robot_description/meshes/leap_hand/dip.stl"/>
      </geometry>
      <material name="dip_material">
        <color rgba="0.86666666666666669627 0.86666666666666669627 0.050980392156862744391 1.0"/>
      </material>
    </visual>
    <collision>
      <origin xyz="0.021133352895225006318 -0.0084321191467048653423 0.0097850881620952373519" rpy="-3.141592653589793116 -1.4095651113919093005e-33 1.5565411607615035382e-32" />
      <geometry>
        <mesh filename="package://denso_robot_description/meshes/leap_hand/dip.stl"/>
      </geometry>
    </collision>
    <inertial>
      <origin xyz="0 0 0" rpy="0 0 0"/>
      <mass value="0.0037" />
      <inertia ixx="0.000005542" ixy="-0.000000607"  ixz="-0.000000017" iyy="0.000005727" iyz="-0.000000023" izz="0.000006682" />
    </inertial>
  </link>

  <link
    name="fingertip_link_3">
    <inertial>
      <origin
        xyz="7.5508E-17 0.010974 -0.01509"
        rpy="0 0 0" />
      <mass
        value="0.0027869" />
      <inertia
        ixx="5.7061E-07"
        ixy="-2.8335E-22"
        ixz="-1.3602E-22"
        iyy="5.3815E-07"
        iyz="5.3399E-10"
        izz="2.1614E-07" />
    </inertial>
    <visual>
      <origin
        xyz="0 0 0"
        rpy="0 0 0" />
      <geometry>
        <mesh
          filename="package://denso_robot_description/meshes/fingertip/meshes/fingertip_link.STL" />
      </geometry>
      <material
        name="">
        <color
          rgba="1 1 1 1" />
      </material>
    </visual>
    <collision>
      <origin
        xyz="0 0 0"
        rpy="0 0 0" />
      <geometry>
        <mesh
          filename="package://denso_robot_description/meshes/fingertip/meshes/fingertip_link.STL" />
      </geometry>
    </collision>
  </link>
  <link
    name="connect_link_3">
    <inertial>
      <origin
        xyz="0.00411765424561172 -0.0148300279082091 0.01775"
        rpy="0 0 0" />
      <mass
        value="0.00557866650364624" />
      <inertia
        ixx="1.54542696836901E-06"
        ixy="-1.85486908918896E-07"
        ixz="-5.33126863056774E-23"
        iyy="7.02952909902168E-07"
        iyz="1.50767782807126E-22"
        izz="1.09293721480962E-06" />
    </inertial>
    <visual>
      <origin
        xyz="0 0 0"
        rpy="0 0 0" />
      <geometry>
        <mesh
          filename="package://denso_robot_description/meshes/fingertip/meshes/connect_link.STL" />
      </geometry>
      <material
        name="">
        <color
          rgba="1 1 1 1" />
      </material>
    </visual>
    <collision>
      <origin
        xyz="0 0 0"
        rpy="0 0 0" />
      <geometry>
        <mesh
          filename="package://denso_robot_description/meshes/fingertip/meshes/connect_link.STL" />
      </geometry>
    </collision>
  </link>
  
  <link
    name="sensor_link_3">
    <inertial>
      <origin
        xyz="5.4530562509196E-06 0.0133276953059358 -5.04567839394631E-05"
        rpy="0 0 0" />
      <mass
        value="0.0178822084472655" />
      <inertia
        ixx="1.1753392286897E-06"
        ixy="4.11684437842668E-12"
        ixz="-2.43892475857913E-11"
        iyy="2.53546070358439E-06"
        iyz="-2.92731609599381E-09"
        izz="1.78912273862224E-06" />
    </inertial>
    <visual>
      <origin
        xyz="0 0 0"
        rpy="0 0 0" />
      <geometry>
        <mesh
          filename="package://denso_robot_description/meshes/fingertip/meshes/sensor_link.STL" />
      </geometry>
      <material
        name="">
        <color
          rgba="1 1 1 1" />
      </material>
    </visual>
    <collision>
      <origin
        xyz="0 0 0"
        rpy="0 0 0" />
      <geometry>
        <mesh
          filename="package://denso_robot_description/meshes/fingertip/meshes/sensor_link.STL" />
      </geometry>
    </collision>
  </link>


  <!-- CREATE HAND LINK 4-->
  <link name="mcp_link_4">
    <visual>
      <origin xyz="-0.0053566369077286714317 0.00029999999999999991951 0.00078403401041737819099" rpy="-1.570796326794896558 -1.570796326794896336 0" />
      <geometry>
        <mesh filename="package://denso_robot_description/meshes/leap_hand/pip.stl"/>
      </geometry>
      <material name="pip_material">
        <color rgba="0.74901960784313725839 0.74901960784313725839 0.74901960784313725839 1.0"/>
      </material>
    </visual>
    <collision>
      <origin xyz="-0.0053566369077286714317 0.00029999999999999991951 0.00078403401041737819099" rpy="-1.570796326794896558 -1.570796326794896336 0" />
      <geometry>
        <mesh filename="package://denso_robot_description/meshes/leap_hand/pip.stl"/>
      </geometry>
    </collision>
    <inertial>
      <origin xyz="0 0 0" rpy="0 0 0"/>
      <mass value="0.0032" />
      <inertia ixx="0.000004798" ixy="0.000000012"  ixz="0.000000004" iyy="0.000002862" iyz="0.000000011" izz="0.000004234" />
    </inertial>
  </link>

  <link name="thumb_pip_link">
    <visual>
      <origin xyz="0.011961920770611186859 -5.3082538364890297089e-16 -0.015852648956664199681" rpy="1.570796326794896558 1.6050198443300152637e-46 -3.9204996250525192755e-59" />
      <geometry>
        <mesh filename="package://denso_robot_description/meshes/leap_hand/thumb_pip.stl"/>
      </geometry>
      <material name="thumb_pip_material">
        <color rgba="0.86666666666666669627 0.86666666666666669627 0.050980392156862744391 1.0"/>
      </material>
    </visual>
    <collision>
    <origin xyz="0.011961920770611186859 -5.3082538364890297089e-16 -0.015852648956664199681" rpy="1.570796326794896558 1.6050198443300152637e-46 -3.9204996250525192755e-59" />
      <geometry>
        <mesh filename="package://denso_robot_description/meshes/leap_hand/thumb_pip.stl"/>
      </geometry>
    </collision>
    <inertial>
      <origin xyz="0 0 0" rpy="0 0 0"/>
      <mass value="0.0003" />
      <inertia ixx="0.000000593" ixy="0"  ixz="0" iyy="0.000000549" iyz="0" izz="0.000000224" />
    </inertial>
  </link>

  <link name="thumb_dip_link">
    <visual>
      <origin xyz="0.043968715707239175439 0.057952952973709198625 -0.0086286764493694757122" rpy="1.9428902930940098942e-16 3.2751579226442200773e-15 1.1123758529657360012e-46" />
      <geometry>
        <mesh filename="package://denso_robot_description/meshes/leap_hand/thumb_dip.stl"/>
      </geometry>
      <material name="thumb_dip_material">
        <color rgba="0.86666666666666669627 0.86666666666666669627 0.050980392156862744391 1.0"/>
      </material>
    </visual>
    <inertial>
      <origin xyz="0 0 0" rpy="0 0 0"/>
      <mass value="0.0038" />
      <inertia ixx="0.000008474" ixy="0.000000241"  ixz="0.000000026" iyy="0.000003841" iyz="0.000000025" izz="0.000007679" />
    </inertial>
  </link>

<link
    name="thumb_motor_link">
    <inertial>
      <origin
        xyz="4.51760295610751E-06 -0.00694199680082334 -0.0142822046034371"
        rpy="0 0 0" />
      <mass
        value="0.0158646274909369" />
      <inertia
        ixx="1.5923173088897E-06"
        ixy="1.37851939825468E-09"
        ixz="-8.3976983238553E-11"
        iyy="6.5414664527114E-07"
        iyz="-2.6599064191085E-09"
        izz="1.85412894058664E-06" />
    </inertial>
    <visual>
      <origin
        xyz="0 0 0"
        rpy="0 0 0" />
      <geometry>
        <mesh
          filename="package://denso_robot_description/meshes/thumb/meshes/motor_link.STL" />
      </geometry>
      <material
        name="">
        <color
          rgba="1 1 1 1" />
      </material>
    </visual>
    <collision>
      <origin
        xyz="0 0 0"
        rpy="0 0 0" />
      <geometry>
        <mesh
          filename="package://denso_robot_description/meshes/thumb/meshes/motor_link.STL" />
      </geometry>
    </collision>
  </link>
  
  <link
    name="thumb_fingertip_link">
    <inertial>
      <origin
        xyz="4.95760791597358E-19 -0.00189387734659092 3.46944695195361E-18"
        rpy="0 0 0" />
      <mass
        value="0.00160614735192622" />
      <inertia
        ixx="1.43117938640444E-07"
        ixy="-5.55047285060956E-24"
        ixz="1.34800551484166E-23"
        iyy="1.97543341584057E-07"
        iyz="1.65264505121979E-23"
        izz="6.03730302729034E-08" />
    </inertial>
    <visual>
      <origin
        xyz="0 0 0"
        rpy="0 0 0" />
      <geometry>
        <mesh
          filename="package://denso_robot_description/meshes/thumb/meshes/thumb_fingertip_link.STL" />
      </geometry>
      <material
        name="">
        <color
          rgba="1 1 1 1" />
      </material>
    </visual>
    <collision>
      <origin
        xyz="0 0 0"
        rpy="0 0 0" />
      <geometry>
        <mesh
          filename="package://denso_robot_description/meshes/thumb/meshes/thumb_fingertip_link.STL" />
      </geometry>
    </collision>
  </link>
  
  <link
    name="thumb_connect_link">
    <inertial>
      <origin
        xyz="0.00411765424561172 -0.0148300279082091 0.01775"
        rpy="0 0 0" />
      <mass
        value="0.00557866650364624" />
      <inertia
        ixx="1.54542696836901E-06"
        ixy="-1.85486908918896E-07"
        ixz="-3.90819007565849E-23"
        iyy="7.02952909902168E-07"
        iyz="1.68799065159474E-22"
        izz="1.09293721480962E-06" />
    </inertial>
    <visual>
      <origin
        xyz="0 0 0"
        rpy="0 0 0" />
      <geometry>
        <mesh
          filename="package://denso_robot_description/meshes/thumb/meshes/connect_link.STL" />
      </geometry>
      <material
        name="">
        <color
          rgba="1 1 1 1" />
      </material>
    </visual>
    <collision>
      <origin
        xyz="0 0 0"
        rpy="0 0 0" />
      <geometry>
        <mesh
          filename="package://denso_robot_description/meshes/thumb/meshes/connect_link.STL" />
      </geometry>
    </collision>
  </link>
  
  <link
    name="thumb_sensor_link">
    <inertial>
      <origin
        xyz="5.45305664510776E-06 0.0133276953142146 -5.04567791665567E-05"
        rpy="0 0 0" />
      <mass
        value="0.0178822084321402" />
      <inertia
        ixx="1.17533922867296E-06"
        ixy="4.11691121828177E-12"
        ixz="-2.43893955468406E-11"
        iyy="2.53546070357286E-06"
        iyz="-2.92731616575703E-09"
        izz="1.78912273854956E-06" />
    </inertial>
    <visual>
      <origin
        xyz="0 0 0"
        rpy="0 0 0" />
      <geometry>
        <mesh
          filename="package://denso_robot_description/meshes/thumb/meshes/sensor_Link.STL" />
      </geometry>
      <material
        name="">
        <color
          rgba="1 1 1 1" />
      </material>
    </visual>
    <collision>
      <origin
        xyz="0 0 0"
        rpy="0 0 0" />
      <geometry>
        <mesh
          filename="package://denso_robot_description/meshes/thumb/meshes/sensor_Link.STL" />
      </geometry>
    </collision>
  </link>
 

  <!-- New virtual link -->
  <link name="real_thumb_link">
    <inertial>
      <origin xyz="0 0 0" rpy="0 0 0" />
      <mass value="0.00001" /> <!-- A small mass for virtual links -->
      <inertia ixx="0.00001" ixy="0" ixz="0" iyy="0.00001" iyz="0" izz="0.00001" />
    </inertial>
  </link>

  <!-- Fixed joint connecting thumb_sensor_link to real_thumb_link -->
  <joint name="thumb_to_real_thumb_joint" type="fixed">
    <parent link="thumb_sensor_link" />
    <child link="real_thumb_link" />
    <origin xyz="0 0.027 0" rpy="-1.57 3.14 0" /> <!-- Offset 0.15 units along y-axis -->
  </joint>

  <!-- HAND JOINTS 1-->
  
  <joint name="mcp_joint_1" type="revolute">
    <origin xyz="-0.0070952496528625457958 0.023057756134899472233 -0.01872240357846021927" rpy="1.57 1.57 0" />
    <parent link="palm_lower" />
    <child link="mcp_link" />
    <axis xyz="0 0 -1"/>
    <limit effort="0.95" velocity="8.48" lower = "-0.314" upper = "2.23"/>
  </joint>
  
  <joint name="pip_joint" type="revolute">
    <origin xyz="-0.012200000000000007713 0.038099999999999994982 0.014500000000000000736" rpy="-1.570796326794896558 -1.0065212660796336576e-15 1.5707963267948943376" />
    <parent link="mcp_link" />
    <child link="pip_link" />
    <axis xyz="0 0 -1"/>
    <limit effort="0.95" velocity="8.48" lower = "-1.047" upper = "1.047"/>
  </joint>

  <joint name="dip_joint" type="revolute">
    <origin xyz="0.01499999999999996822 0.014299999999999904801 -0.012999999999999824196" rpy="1.5707963267948958919 -1.570796326794896336 0" />
    <parent link="pip_link" />
    <child link="dip_link" />
    <axis xyz="0 0 -1"/>
    <limit effort="0.95" velocity="8.48" lower = "-0.506" upper = "1.885"/> 
  </joint>

  <joint name="fingertip_joint" type="revolute">
    <origin xyz="-4.0880582495572692636e-09 -0.036100004210367367397 0.00020000000000007858714" rpy="4.5935029425113685044e-17 -2.8730071914463794583e-16 4.4395481053923607589e-32" />
    <parent link="dip_link" />
    <child link="fingertip_link" />
    <axis xyz="0 0 -1"/>
    <limit effort="0.95" velocity="8.48" lower = "-0.366" upper = "2.042"/>
  </joint>

  <!-- HAND JOINTS 2-->
  <joint name="mcp_joint_2" type="revolute">
    <origin xyz="-0.0070952496528625388569 -0.022392243865100525113 -0.018722403578460229678" rpy="1.570796326794896558 1.570796326794896558 0" />
    <parent link="palm_lower" />
    <child link="mcp_link_2" />
    <axis xyz="0 0 -1"/>
    <limit effort="0.95" velocity="8.48" lower = "-0.314" upper = "2.23"/>
  </joint>

  <joint name="pip_joint_2" type="revolute">
    <origin xyz="-0.012200000000000019856 0.038099999999999981104 0.01450000000000000594" rpy="-1.570796326794896558 -1.0065212760057939085e-15 1.5707963267948943376" />
    <parent link="mcp_link_2" />
    <child link="pip_link_2" />
    <axis xyz="0 0 -1"/>
    <limit effort="0.95" velocity="8.48" lower = "-1.047" upper = "1.047"/>
  </joint>

  <joint name="dip_joint_2" type="revolute">
    <origin xyz="0.014999999999999975159 0.014300000000000000211 -0.013000000000000018485" rpy="1.5707963267948958919 -1.570796326794896336 0" />
    <parent link="pip_link_2" />
    <child link="dip_link_2" />
    <axis xyz="0 0 -1"/>
    <limit effort="0.95" velocity="8.48" lower = "-0.506" upper = "1.885"/>
  </joint>

  <joint name="fingertip_joint_2" type="revolute">
    <origin xyz="1.0061396160665481148e-16 -0.036099999999999854428 0.00020000000000007858714" rpy="4.5935029425113654229e-17 -2.8730071914463794583e-16 1.4408183216511868558e-31" />
    <parent link="dip_link_2" />
    <child link="fingertip_link_2" />
    <axis xyz="0 0 -1"/>
    <limit effort="0.95" velocity="8.48" lower = "-0.366" upper = "2.042"/>
  </joint>

  <!-- HAND JOINTS 3-->

  <joint name="mcp_joint_3" type="revolute">
    <origin xyz="-0.0070952454426398371343 -0.067842243865100515521 -0.018722403578460229678" rpy="1.5707963267948950037 1.5707963267948945596 0" />
    <parent link="palm_lower" />
    <child link="mcp_link_3" />
    <axis xyz="0 0 -1"/>
    <limit effort="0.95" velocity="8.48" lower = "-0.314" upper = "2.23"/>
  </joint>

  <joint name="pip_joint_3" type="revolute">
    <origin xyz="-0.012200000000000004244 0.038100000000000001921 0.014499999999999999001" rpy="-1.570796326794896558 -1.0065212660796360242e-15 1.5707963267948943376" />
    <parent link="mcp_link_3" />
    <child link="pip_link_3" />
    <axis xyz="0 0 -1"/>
    <limit effort="0.95" velocity="8.48" lower = "-1.047" upper = "1.047"/>
  </joint>


  <joint name="dip_joint_3" type="revolute">
    <origin xyz="0.014999999999999971689 0.014299999999999951639 -0.012999999999999959505" rpy="1.5707963267948958919 -1.570796326794896336 0" />
    <parent link="pip_link_3" />
    <child link="dip_link_3" />
    <axis xyz="0 0 -1"/>
    <limit effort="0.95" velocity="8.48" lower = "-0.506" upper = "1.885"/>
  </joint>

  <joint name="fingertip_joint_3" type="revolute">
    <origin xyz="9.7144514654701197287e-17 -0.036099999999999868305 0.00020000000000007511769" rpy="4.5935029425113685044e-17 -2.8730071914463799514e-16 1.5565411607615035382e-32" />
    <parent link="dip_link_3" />
    <child link="fingertip_link_3" />
    <axis xyz="0 0 -1"/>
    <limit effort="0.95" velocity="8.48" lower = "-0.366" upper = "2.042"/>
  </joint>

  <!-- HAND JOINTS 4-->
  <joint name="mcp_joint_4" type="revolute">
    <origin xyz="-0.069395249652862533996 -0.0012422438651005258004 -0.021622403578460215601" rpy="-8.2381766464939424156e-17 1.5707963267948956698 0" />
    <parent link="palm_lower" />
    <child link="mcp_link_4" />
    <axis xyz="0 0 -1"/>
    <limit effort="0.95" velocity="8.48" lower = "-0.349" upper = "2.094"/>
  </joint>

  <joint name="thumb_pip_joint" type="revolute">
    <origin xyz="-2.7755575615628913511e-17 0.014300000000000005415 -0.013000000000000011546" rpy="1.5707963267948958919 -1.570796326794896336 0" />
    <parent link="mcp_link_4" />
    <child link="thumb_pip_link" />
    <axis xyz="0 0 -1"/>
    <limit effort="0.95" velocity="8.48" lower = "-0.47" upper = "2.443"/>
  </joint>

  <joint name="thumb_dip_joint" type="revolute">
    <origin xyz="0 0.014499999999999966041 -0.017000000000000053263" rpy="-1.570796326794896558 1.6050198443300131245e-46 -1.9721522630516624601e-31" />
    <parent link="thumb_pip_link" />
    <child link="thumb_dip_link" />
    <axis xyz="0 0 -1"/>
    <limit effort="0.95" velocity="8.48" lower = "-1.20" upper = "1.90"/>
  </joint>

  <joint name="thumb_motor_joint" type="revolute">
    <origin xyz="-1.249000902703301108e-16 0.046599999999999863753 0.00019999999999997710581" rpy="1.5063958491491781023e-44 5.4234187233935260503e-31 3.141592653589793116" />
    <parent link="thumb_dip_link" />
    <child link="thumb_motor_link" />
    <axis xyz="0 0 -1"/>
    <limit effort="0.95" velocity="8.48" lower = "-1.34" upper = "1.88"/>
  </joint>
  
  <joint
    name="connect_joint"
    type="fixed">
    <origin
      xyz="0.00799999999999977 -0.017 0.03275"
      rpy="3.14159265358979 0 3.14159265358979" />
    <parent
      link="fingertip_link" />
    <child
      link="connect_link" />
    <axis
      xyz="0 0 0" />
  </joint>
  
  <joint
    name="sensor_joint"
    type="fixed">
    <origin
      xyz="0.00300000000000001 -0.02575 0.01775"
      rpy="0 0 -1.5707963267949" />
    <parent
      link="connect_link" />
    <child
      link="sensor_link" />
    <axis
      xyz="0 0 0" />
  </joint>
  
  <joint
    name="connect_joint_2"
    type="fixed">
    <origin
      xyz="0.00799999999999977 -0.017 0.03275"
      rpy="3.14159265358979 0 3.14159265358979" />
    <parent link="fingertip_link_2" />
    <child link="connect_link_2" />
    <axis
      xyz="0 0 0" />
  </joint>
  
  <joint
    name="sensor_joint_2"
    type="fixed">
    <origin
      xyz="0.00300000000000001 -0.02575 0.01775"
      rpy="0 0 -1.5707963267949" />
    <parent
      link="connect_link_2" />
    <child
      link="sensor_link_2" />
    <axis
      xyz="0 0 0" />
  </joint>


  <joint
    name="connect_joint_3"
    type="fixed">
    <origin
      xyz="0.00799999999999977 -0.017 0.03275"
      rpy="3.14159265358979 0 3.14159265358979" />
    <parent link="fingertip_link_3" />
    <child link="connect_link_3" />
    <axis
      xyz="0 0 0" />
  </joint>
  
  <joint
    name="sensor_joint_3"
    type="fixed">
    <origin
      xyz="0.00300000000000001 -0.02575 0.01775"
      rpy="0 0 -1.5707963267949" />
    <parent
      link="connect_link_3" />
    <child
      link="sensor_link_3" />
    <axis
      xyz="0 0 0" />
  </joint>
  
  <joint
    name="thumb_fingertip_joint"
    type="fixed">
    <origin
      xyz="0 -0.0275 -0.014500000000011"
      rpy="0 0 3.14159265358979" />
    <parent
      link="thumb_motor_link" />
    <child
      link="thumb_fingertip_link" />
    <axis
      xyz="0 0 0" />
  </joint>
  
  <joint
    name="thumb_connect_joint"
    type="fixed">
    <origin
      xyz="-0.008 0 0.01775"
      rpy="-3.14159265358979 0 0" />
    <parent
      link="thumb_fingertip_link" />
    <child
      link="thumb_connect_link" />
    <axis
      xyz="0 0 0" />
  </joint>
  
  <joint
    name="thumb_sensor_joint"
    type="fixed">
    <origin
      xyz="0.003 -0.02575 0.01775"
      rpy="3.14159265358979 0 1.5707963267949" />
    <parent
      link="thumb_connect_link" />
    <child
      link="thumb_sensor_link" />
    <axis
      xyz="0 0 0" />
  </joint>
  

  <!-- New virtual link -->
  <link name="real_index_link">
    <inertial>
      <origin xyz="0 0 0" rpy="0 0 0" />
      <mass value="0.00001" /> <!-- A small mass for virtual links -->
      <inertia ixx="0.00001" ixy="0" ixz="0" iyy="0.00001" iyz="0" izz="0.00001" />
    </inertial>
  </link>

  <!-- Fixed joint connecting thumb_sensor_link to real_thumb_link -->
  <joint name="index_to_real_index_joint" type="fixed">
    <parent link="sensor_link" />
    <child link="real_index_link" />
    <origin xyz="0 0.027 0" rpy="-1.57 0 0" /> <!-- Offset 0.15 units along y-axis -->
  </joint>

  <!-- New virtual link -->
  <link name="real_middle_link">
    <inertial>
      <origin xyz="0 0 0" rpy="0 0 0" />
      <mass value="0.00001" /> <!-- A small mass for virtual
      links -->
      <inertia ixx="0.00001" ixy="0" ixz="0" iyy="0.00001" iyz="0" izz="0.00001" />
    </inertial>
  </link>

  <!-- Fixed joint connecting thumb_sensor_link to real_thumb_link -->
  <joint name="middle_to_real_middle_joint" type="fixed">
    <parent link="sensor_link_2" />
    <child link="real_middle_link" />
    <origin xyz="0 0.027 0" rpy="-1.57 0 0" /> <!-- Offset 0.15 units along y-axis -->
  </joint>


  
  <gazebo>
    <!-- Joint state publisher -->
    <plugin filename="ign_ros2_control-system" name="ign_ros2_control::IgnitionROS2ControlPlugin">
      <parameters>/home/ruiqiang/workspaces/denso_ws/install/denso_robot_bringup/share/denso_robot_bringup/config/denso_robot_gazebo_controllers.yaml</parameters>
    </plugin>
  </gazebo>
</robot>
