<robot name="onshape">
  <!-- Existing palm_lower link -->
  <link name="palm_upper">
    <visual>
      <origin xyz="-0.020095249652862544332 0.025757756134899473244 -0.034722403578460216134" rpy="0 -0 0" />
      <geometry>
        <mesh filename="package://denso_robot_description/meshes/leap_hand/palm_upper_denso_correct.stl"/>
      </geometry>
      <material name="palm_lower_material">
        <color rgba="0.60392156862745094426 0.14901960784313725283 0.14901960784313725283 1.0"/>
      </material>
    </visual>
    <collision>
      <origin xyz="-0.020095249652862544332 0.025757756134899473244 -0.034722403578460216134" rpy="0 -0 0" />
      <geometry>
        <mesh filename="package://denso_robot_description/meshes/leap_hand/palm_upper_denso_correct.stl"/>
      </geometry>
    </collision>
    <inertial>
      <origin xyz="0 0 0" rpy="0 0 0"/>
      <mass value="0.237" />
      <inertia ixx="0.000354094" ixy="-0.000001193"  ixz="-0.000002445" iyy="0.000260915" iyz="-0.000002905" izz="0.000529257" />
    </inertial>
  </link>

  <!-- Virtual fixed joint to bind the robot to the world -->
  <link name="world"/>
  <joint name="fixed_world_joint" type="fixed">
    <origin xyz="0 0 0" rpy="0 0 0"/>
    <parent link="world"/>
    <child link="palm_upper"/>
  </joint>

  <!-- Existing mcp_joint link -->
  <link name="mcp_joint">
    <visual>
      <origin xyz="0.0084069022611744960438 0.0077662438597169954416 0.014657354985032912051" rpy="1.6375789613220999807e-15 -1.0210473302491019535e-30 1.7177968783327987474e-31" />
      <geometry>
        <mesh filename="package://denso_robot_description/meshes/leap_hand/mcp_joint.stl"/>
      </geometry>
      <material name="mcp_joint_material">
        <color rgba="0.86666666666666669627 0.86666666666666669627 0.050980392156862744391 1.0"/>
      </material>
    </visual>
    <collision>
      <origin xyz="0.0084069022611744960438 0.0077662438597169954416 0.014657354985032912051" rpy="1.6375789613220999807e-15 -1.0210473302491019535e-30 1.7177968783327987474e-31" />
      <geometry>
        <mesh filename="package://denso_robot_description/meshes/leap_hand/mcp_joint.stl"/>
      </geometry>
    </collision>
    <inertial>
      <origin xyz="0 0 0" rpy="0 0 0"/>
      <mass value="0.044" />
      <inertia ixx="0.000011499" ixy="0.000003049"  ixz="0.000000121" iyy="0.000007796" iyz="0.000000112" izz="0.000014759" />
    </inertial>
  </link>

  <joint name="1" type="revolute">
    <origin xyz="-0.0070952496528625457958 0.023057756134899472233 -0.01872240357846021927" rpy="1.5707963267948950037 1.5707963267948945596 0" />
    <parent link="palm_upper" />
    <child link="mcp_joint" />
    <axis xyz="0 0 -1"/>
    <limit effort="0.95" velocity="8.48" lower="-0.314" upper="2.23"/>
    <joint_properties friction="0.0"/>
  </joint>
  
</robot>

